<?xml version="1.0"?>
<robot xmlns:xacro="http://www.ros.org/wiki/xacro" name="first_robot">
    <xacro:include filename="$(find fishbot_description)/urdf/fishbot/common_inertia.xacro"/>

    <xacro:macro name="wheel_xacro" params="wheel_name xyz" >
        <!-- wheel -->
        <link name="${wheel_name}_link">
            
            <visual>
                
                <origin xyz="0.0 0.0 0.0" rpy="1.57079 0.0 0.0"/>
                
                <geometry>
                    <cylinder radius="0.032" length="0.04"/>
                </geometry>
                
                <material name="yellow">
                    <color rgba="1.0 1.0 0.0 0.8"/>
                </material>
            </visual>
            <collision>
                <origin xyz="0.0 0.0 0.0" rpy="1.57079 0.0 0.0"/>
                
                <geometry>
                    <cylinder radius="0.032" length="0.04"/>
                </geometry>
                
                <material name="yellow">
                    <color rgba="1.0 1.0 0.0 0.8"/>
                </material>
            </collision>

            <xacro:cylinder_inertia m="0.05" r="0.032" h="0.04"/>
        </link>

    
        <joint name="${wheel_name}_joint" type="continuous">
            <parent link="base_link"/>
            <child link="${wheel_name}_link"/>
            <origin xyz="${xyz}" rpy="0.0 0.0 0.0"/>
            <!--axis-->
            <axis xyz="0 1 0"/>
        </joint>

        
        <gazebo reference="${wheel_name}_link">
            <mu1 value="20.0"/> <!-- mu1表示沿着第一个轴的摩擦系数 -->
            <mu2 value="20.0"/> <!-- mu2表示沿着第二个轴的摩擦系数 -->
            <kp value="1000000000.0"/> <!-- kp表示弹簧刚度系数 -->
            <kd value="1.0"/> <!-- kd表示阻尼系数 -->
            <material>Gazebo/Black</material>
        </gazebo>

    </xacro:macro>


</robot>